<?xml version="1.0"?>
<robot xmlns:xacro="http://www.ros.org/wiki/xacro" name="wheel">

    <!-- Include the radio_wheel.URDF.XACRO file -->
    <xacro:include filename="$(find hermes_description)/urdf/wheel/radio_wheel.urdf.xacro"/>
    <!-- Macro to create a wheel -->
    <xacro:macro name="create_wheel" params="name parent_link xyz rpy">

        <!-- Center plane -->
        <link name="${name}_center_plane_link">
            <inertial>
                <mass value="0.5"/>
                <inertia ixx="0.01" ixy="0" ixz="0" iyy="0.01" iyz="0" izz="0.01"/>
            </inertial>
            <visual>
                <geometry>
                    <cylinder length="0.02" radius="0.06"/>
                </geometry>
                <material name="center_plane_color"/>
            </visual>
            <collision>
                <geometry>
                    <cylinder length="0.02" radius="0.06"/>
                </geometry>
            </collision>
        </link>
        <joint name="${name}_center_plane_joint" type="continuous">
            <parent link="${parent_link}"/>
            <child link="${name}_center_plane_link"/>
            <origin xyz="${xyz}" rpy="${rpy}"/>
            <axis xyz="0 0 -1"/>
        </joint>

        <!-- Center cone -->
        <link name="${name}_center_cone_link">
            <inertial>
                <mass value="1.0"/>
                <inertia ixx="0.02" ixy="0" ixz="0" iyy="0.02" iyz="0" izz="0.02"/>
            </inertial>
            <visual>
                <geometry>
                    <mesh filename="package://hermes_description/meshes/dae/Cone.013.dae" scale="0.06 0.06 0.015"/>
                </geometry>
                <material name="center_cone_color"/>
            </visual>
            <collision>
                <geometry>
                    <mesh filename="package://hermes_description/meshes/dae/Cone.013.dae" scale="0.06 0.06 0.015"/>
                </geometry>
            </collision>
        </link>
        <joint name="${name}_center_cone_joint" type="fixed">
            <parent link="${name}_center_plane_link"/>
            <child link="${name}_center_cone_link"/>
            <origin xyz="0 0 0" rpy="0 0 0"/>
        </joint>

        <!-- Tire -->
        <link name="${name}_tire_link">
            <inertial>
                <mass value="10"/>
                <inertia ixx="0.65832" ixy="0" ixz="0" iyy="0.36033" iyz="0" izz="0.36033"/>
            </inertial>
            <visual>
                <geometry>
                    <mesh filename="package://hermes_description/meshes/dae/Cone.058.dae" scale="0.06000 0.06000 0.01500"/>
                </geometry>
                <material name="tire_color"/>
            </visual>
            <collision>
                <geometry>
                    <mesh filename="package://hermes_description/meshes/dae/Cone.058.dae" scale="0.06000 0.06000 0.01500"/>
                </geometry>
                <surface>
                    <friction>
                        <ode>
                            <mu>1</mu>
                            <mu2>1</mu2>
                            <fdir1>0 0 1</fdir1>
                            <slip1>0.5</slip1>
                            <slip2>0.5</slip2>
                        </ode>
                    </friction>
                </surface>
            </collision>
        </link>

        <joint name="${name}_tire_joint" type="fixed">
            <parent link="${name}_center_cone_link"/>
            <child link="${name}_tire_link"/>
            <origin xyz="0 0 -0.10091" rpy="0 0 0"/>
        </joint>

        <!-- Spokes -->
        <xacro:create_wheel_spoke name="${name}_spoke1" parent_link="${name}_center_plane_link" rpy="0 0 0"/>
        <xacro:create_wheel_spoke name="${name}_spoke2" parent_link="${name}_center_plane_link" rpy="0 0 0.7854"/>
        <xacro:create_wheel_spoke name="${name}_spoke3" parent_link="${name}_center_plane_link" rpy="0 0 1.5708"/>
        <xacro:create_wheel_spoke name="${name}_spoke4" parent_link="${name}_center_plane_link" rpy="0 0 2.35619"/>

        <!-- Tranmission -->
        <transmission name="${name}_wheel_transmission">
            <type>transmission_interface/SimpleTransmission</type>
            <joint name="${name}_center_plane_joint">
                <hardwareInterface>EffortJointInterface</hardwareInterface>
            </joint>
            <actuator name="${name}_wheel_motor">
                <hardwareInterface>EffortJointInterface</hardwareInterface>
                <mechanicalReduction>1</mechanicalReduction>
            </actuator>
        </transmission>

        <!-- Friccion gazebo, no necesaria ya que con la friccion de las ruedas vale-->
        <gazebo reference="${name}_tire_link">
            <mu1>5</mu1>
            <mu2>5</mu2>
            <!--<kp>2.75e6</kp>-->
            <kd>8.25e1</kd>
            <fdir1>0 0 0</fdir1>
            <!--<maxContacts>4</maxContacts>-->
        </gazebo>
    </xacro:macro>

    <!-- Materials -->
    <material name="center_cone_color">
        <color rgba="0.09412 0.10980 0.21961 1.00000"/>
    </material>

    <material name="center_plane_color">
        <color rgba="0.01961 0.02353 0.04706 1.00000"/>
    </material>
</robot>